Workbook

Sheet Inputs
A1: All Court Academy – prijscalculator events (inkoop Poort Padel + marge)
A2: Blauw = invoer die je mag wijzigen. Geel = aanname, nog te verifiëren bij Poort Padel. Zwart = formule.
A4: Sleutel | B4: Omschrijving | C4: Waarde | D4: Eenheid | E4: Status | F4: Bron / toelichting
A5: marge | B5: Winstmarge All Court Academy bovenop kostprijs | C5: 0.2 | D5: % | E5: Keuze Lars | F5: Opdracht: +20%
A6: btw | B6: BTW-tarief (sport/clinics 9%, horeca 9%, zaalhuur 21%) – info | C6: 0.21 | D6: % | E6: Info | F6: Belastingdienst; prijzen in dit bestand zijn excl. btw
B7: — Baanhuur dubbelbaan (Playtomic, geverifieerd 9 sep 2026) —
A8: baan_dal | B8: Dubbelbaan daluren ma–vr 07:00–17:00, per uur | C8: 30 | D8: €/uur | E8: Geverifieerd | F8: playtomic.com/nl/clubs/poort-padel
A9: baan_piek | B9: Dubbelbaan piek ma–vr vanaf 17:00, per uur | C9: 44 | D9: €/uur | E9: Geverifieerd | F9: playtomic.com/nl/clubs/poort-padel
A10: baan_wknd | B10: Dubbelbaan weekend za/zo, per uur | C10: 37.5 | D10: €/uur | E10: Geverifieerd | F10: playtomic.com/nl/clubs/poort-padel
A11: spelers_per_baan | B11: Spelers per baan bij events | C11: 4 | D11: pers. | E11: Keuze Lars | F11: Standaard dubbelspel
B12: — Coaching (intern All Court Academy) —
A13: coach_uur | B13: Kostprijs coach per uur (incl. reistijd/voorbereiding) | C13: 45 | D13: €/uur | E13: AANNAME | F13: Vul eigen coachtarief in
A14: spelers_per_coach | B14: Spelers per coach bij een clinic | C14: 8 | D14: pers. | E14: Keuze Lars | F14: 2 banen per coach
A15: spelers_per_leider | B15: Spelers per toernooileider | C15: 16 | D15: pers. | E15: Keuze Lars | F15: 4 banen per begeleider
A16: ballen_per_baan | B16: Ballen per baan per event | C16: 2 | D16: €/baan | E16: AANNAME | F16: Eigen inkoop ACA
A17: prijzen_event | B17: Prijsjes/medailles per toernooi | C17: 25 | D17: €/event | E17: AANNAME | F17: Eigen inkoop ACA
A18: racket_huur | B18: Rackethuur per persoon (0 = leenrackets ACA) | C18: 0 | D18: €/pers. | E18: AANNAME | F18: Poort Padel balieprijs niet online
B19: — Horeca Poort Padel (menukaart juni 2026) —
A20: drankje | B20: Gemiddelde prijs per drankje (bier/fris/wijn) | C20: 3.75 | D20: € | E20: AANNAME | F20: Wijn €5–6,50 op de kaart; bier/fris niet online
A21: hapje | B21: Prijs per borrelhapje (teamschotel 25 st €24,50) | C21: 0.98 | D21: € | E21: Geverifieerd | F21: Menukaart PDF
A22: koffie | B22: Koffie/thee per kop | C22: 3 | D22: € | E22: AANNAME | F22: Niet op online kaart
A23: lunch_item | B23: Lunchgerecht gemiddeld (sandwich €10,50–14,50) | C23: 12.5 | D23: € | E23: Geverifieerd | F23: Menukaart PDF
A24: diner_item | B24: Dinergerecht gemiddeld (burger €17,50 / saté €19,50) | C24: 18.5 | D24: € | E24: Geverifieerd | F24: Menukaart PDF
B25: — Zaalhuur Poort Padel (reserveren.poortpadel.nl, geverifieerd 6 sep 2026, excl. 21% btw) —
A26: zaal_kantoor_dagdeel | B26: Vergaderzaal/kantoor (10–12 pers.) per dagdeel (max 4 uur) | C26: 225 | D26: €/dagdeel | E26: Geverifieerd | F26: AQQO-wizard: 1 uur en 4 uur = €225; ook op zaterdag
A27: zaal_kantoor_dag | B27: Vergaderzaal/kantoor hele dag 08:00–17:00 | C27: 400 | D27: €/dag | E27: Geverifieerd | F27: AQQO-wizard: 08:00–17:00 = €400
A28: zaal_skybox_dagdeel | B28: Skybox Londen/Parijs per dagdeel (max 4 uur) | C28: 250 | D28: €/dagdeel | E28: Geverifieerd | F28: AQQO-wizard: 1 uur en 4 uur = €250
A29: zaal_skybox_dag | B29: Skybox Londen/Parijs hele dag 08:00–17:00 | C29: 500 | D29: €/dag | E29: Geverifieerd | F29: AQQO-wizard: 08:00–17:00 = €500
A30: zaal_congres_dagdeel | B30: Congreszaal Amsterdam (max 110) per dagdeel (max 4 uur) | C30: 550 | D30: €/dagdeel | E30: Geverifieerd | F30: AQQO-wizard: 1 uur en 4 uur = €550
A31: zaal_congres_dag | B31: Congreszaal Amsterdam hele dag 08:00–17:00 | C31: 1000 | D31: €/dag | E31: Geverifieerd | F31: AQQO-wizard: 08:00–17:00 = €1.000
A32: zaal_event_dagdeel | B32: Evenementenruimte (20–150) per dagdeel overdag (max 4 uur) | C32: 450 | D32: €/dagdeel | E32: Geverifieerd | F32: AQQO-wizard: 1 uur en 4 uur = €450
A33: zaal_event_avond | B33: Evenementenruimte avond 18:00–22:00 | C33: 550 | D33: €/avond | E33: Geverifieerd | F33: AQQO-wizard: 18:00–22:00 = €550
A34: zaal_event_dag | B34: Evenementenruimte hele dag 08:00–17:00 | C34: 850 | D34: €/dag | E34: Geverifieerd | F34: AQQO-wizard: 08:00–17:00 = €850
B35: — Scholen —
A36: leerlingen_per_baan | B36: Leerlingen per baan bij schoolclinic (roterend) | C36: 6 | D36: pers. | E36: Keuze Lars | F36: Bij 30 leerlingen = 5 banen
A37: afronding | B37: Verkoopprijs afronden op (bv. 0,50) | C37: 0.5 | D37: € | E37: Keuze Lars

Sheet Arrangementen
A1: Zakelijke padelarrangementen – prijs per persoon (excl. btw, excl. horeca)
A2: Minimum 16 personen (eis Poort Padel). Kostprijs = baanhuur/spelers + coach + toernooileider + prijzen + ballen. Verkoop = kostprijs x (1+marge).
A4: Pakket | B4: Duur baan (uur) | C4: Clinic-uren coach | D4: Toernooi-uren leider | E4: Prijzen? | F4: Kostprijs daluren | G4: Kostprijs piek | H4: Kostprijs weekend | I4: Verkoop daluren | J4: Verkoop piek | K4: Verkoop weekend
A5: A. Vrij spel (90 min) | B5: 1.5 | C5: 0 | D5: 0 | E5: 0 | F5: =B5*Inputs!$C$8/Inputs!$C$11+C5*Inputs!$C$13/Inputs!$C$14+D5*Inputs!$C$13/Inputs!$C$15+E5*Inputs!$C$17/Inputs!$C$15+Inputs!$C$16/Inputs!$C$11+Inputs!$C$18 -> 11.75 | G5: =B5*Inputs!$C$9/Inputs!$C$11+C5*Inputs!$C$13/Inputs!$C$14+D5*Inputs!$C$13/Inputs!$C$15+E5*Inputs!$C$17/Inputs!$C$15+Inputs!$C$16/Inputs!$C$11+Inputs!$C$18 -> 17 | H5: =B5*Inputs!$C$10/Inputs!$C$11+C5*Inputs!$C$13/Inputs!$C$14+D5*Inputs!$C$13/Inputs!$C$15+E5*Inputs!$C$17/Inputs!$C$15+Inputs!$C$16/Inputs!$C$11+Inputs!$C$18 -> 14.5625 | I5: =CEILING((F5)*(1+Inputs!$C$5),Inputs!$C$37) -> 14.5 | J5: =CEILING((G5)*(1+Inputs!$C$5),Inputs!$C$37) -> 20.5 | K5: =CEILING((H5)*(1+Inputs!$C$5),Inputs!$C$37) -> 17.5
A6: B. Clinic + vrij spel (2 uur) | B6: 2 | C6: 1 | D6: 0 | E6: 0 | F6: =B6*Inputs!$C$8/Inputs!$C$11+C6*Inputs!$C$13/Inputs!$C$14+D6*Inputs!$C$13/Inputs!$C$15+E6*Inputs!$C$17/Inputs!$C$15+Inputs!$C$16/Inputs!$C$11+Inputs!$C$18 -> 21.125 | G6: =B6*Inputs!$C$9/Inputs!$C$11+C6*Inputs!$C$13/Inputs!$C$14+D6*Inputs!$C$13/Inputs!$C$15+E6*Inputs!$C$17/Inputs!$C$15+Inputs!$C$16/Inputs!$C$11+Inputs!$C$18 -> 28.125 | H6: =B6*Inputs!$C$10/Inputs!$C$11+C6*Inputs!$C$13/Inputs!$C$14+D6*Inputs!$C$13/Inputs!$C$15+E6*Inputs!$C$17/Inputs!$C$15+Inputs!$C$16/Inputs!$C$11+Inputs!$C$18 -> 24.875 | I6: =CEILING((F6)*(1+Inputs!$C$5),Inputs!$C$37) -> 25.5 | J6: =CEILING((G6)*(1+Inputs!$C$5),Inputs!$C$37) -> 34 | K6: =CEILING((H6)*(1+Inputs!$C$5),Inputs!$C$37) -> 30
A7: C. Toernooi (2 uur, Mexicano / King of the Court) | B7: 2 | C7: 0 | D7: 2 | E7: 1 | F7: =B7*Inputs!$C$8/Inputs!$C$11+C7*Inputs!$C$13/Inputs!$C$14+D7*Inputs!$C$13/Inputs!$C$15+E7*Inputs!$C$17/Inputs!$C$15+Inputs!$C$16/Inputs!$C$11+Inputs!$C$18 -> 22.6875 | G7: =B7*Inputs!$C$9/Inputs!$C$11+C7*Inputs!$C$13/Inputs!$C$14+D7*Inputs!$C$13/Inputs!$C$15+E7*Inputs!$C$17/Inputs!$C$15+Inputs!$C$16/Inputs!$C$11+Inputs!$C$18 -> 29.6875 | H7: =B7*Inputs!$C$10/Inputs!$C$11+C7*Inputs!$C$13/Inputs!$C$14+D7*Inputs!$C$13/Inputs!$C$15+E7*Inputs!$C$17/Inputs!$C$15+Inputs!$C$16/Inputs!$C$11+Inputs!$C$18 -> 26.4375 | I7: =CEILING((F7)*(1+Inputs!$C$5),Inputs!$C$37) -> 27.5 | J7: =CEILING((G7)*(1+Inputs!$C$5),Inputs!$C$37) -> 36 | K7: =CEILING((H7)*(1+Inputs!$C$5),Inputs!$C$37) -> 32
A8: D. Clinic + toernooi (3 uur) | B8: 3 | C8: 1 | D8: 2 | E8: 1 | F8: =B8*Inputs!$C$8/Inputs!$C$11+C8*Inputs!$C$13/Inputs!$C$14+D8*Inputs!$C$13/Inputs!$C$15+E8*Inputs!$C$17/Inputs!$C$15+Inputs!$C$16/Inputs!$C$11+Inputs!$C$18 -> 35.8125 | G8: =B8*Inputs!$C$9/Inputs!$C$11+C8*Inputs!$C$13/Inputs!$C$14+D8*Inputs!$C$13/Inputs!$C$15+E8*Inputs!$C$17/Inputs!$C$15+Inputs!$C$16/Inputs!$C$11+Inputs!$C$18 -> 46.3125 | H8: =B8*Inputs!$C$10/Inputs!$C$11+C8*Inputs!$C$13/Inputs!$C$14+D8*Inputs!$C$13/Inputs!$C$15+E8*Inputs!$C$17/Inputs!$C$15+Inputs!$C$16/Inputs!$C$11+Inputs!$C$18 -> 41.4375 | I8: =CEILING((F8)*(1+Inputs!$C$5),Inputs!$C$37) -> 43 | J8: =CEILING((G8)*(1+Inputs!$C$5),Inputs!$C$37) -> 56 | K8: =CEILING((H8)*(1+Inputs!$C$5),Inputs!$C$37) -> 50
A9: E. Padel Experience XL (4 uur: clinic, toernooi, vrij spel) | B9: 4 | C9: 1 | D9: 2 | E9: 1 | F9: =B9*Inputs!$C$8/Inputs!$C$11+C9*Inputs!$C$13/Inputs!$C$14+D9*Inputs!$C$13/Inputs!$C$15+E9*Inputs!$C$17/Inputs!$C$15+Inputs!$C$16/Inputs!$C$11+Inputs!$C$18 -> 43.3125 | G9: =B9*Inputs!$C$9/Inputs!$C$11+C9*Inputs!$C$13/Inputs!$C$14+D9*Inputs!$C$13/Inputs!$C$15+E9*Inputs!$C$17/Inputs!$C$15+Inputs!$C$16/Inputs!$C$11+Inputs!$C$18 -> 57.3125 | H9: =B9*Inputs!$C$10/Inputs!$C$11+C9*Inputs!$C$13/Inputs!$C$14+D9*Inputs!$C$13/Inputs!$C$15+E9*Inputs!$C$17/Inputs!$C$15+Inputs!$C$16/Inputs!$C$11+Inputs!$C$18 -> 50.8125 | I9: =CEILING((F9)*(1+Inputs!$C$5),Inputs!$C$37) -> 52 | J9: =CEILING((G9)*(1+Inputs!$C$5),Inputs!$C$37) -> 69 | K9: =CEILING((H9)*(1+Inputs!$C$5),Inputs!$C$37) -> 61
A11: Toelichting
A12: Daluren = ma–vr 07:00–17:00. Piek = ma–vr vanaf 17:00. Weekend = za/zo.
A13: Clinic-uren coach: uren dat een coach voor elke groep van 'spelers per coach' actief is.
A14: Toernooi-uren leider: uren toernooileiding per groep van 'spelers per toernooileider'.
A15: Prijzen? = 1 als er prijsjes/medailles worden uitgereikt.
A16: Horeca, zaalhuur en workshops komen hier bovenop (zie tabblad Add-ons).

Sheet Add-ons
A1: Add-ons per persoon of per zaal (excl. btw)
A3: Add-on | B3: Samenstelling | C3: Kostprijs | D3: Verkoopprijs | E3: Eenheid
A4: Koffie/thee bij ontvangst | B4: 2 kopjes p.p. | C4: =2*Inputs!$C$22 -> 6 | D4: =CEILING((C4)*(1+Inputs!$C$5),Inputs!$C$37) -> 7.5 | E4: p.p.
A5: Borrelarrangement | B5: 2 drankjes + 4 hapjes p.p. | C5: =2*Inputs!$C$20+4*Inputs!$C$21 -> 11.42 | D5: =CEILING((C5)*(1+Inputs!$C$5),Inputs!$C$37) -> 14 | E5: p.p.
A6: Borrelarrangement XL | B6: 3 drankjes + 6 hapjes p.p. | C6: =3*Inputs!$C$20+6*Inputs!$C$21 -> 17.13 | D6: =CEILING((C6)*(1+Inputs!$C$5),Inputs!$C$37) -> 21 | E6: p.p.
A7: Lunch | B7: lunchgerecht + drankje + koffie | C7: =Inputs!$C$23+Inputs!$C$20+Inputs!$C$22 -> 19.25 | D7: =CEILING((C7)*(1+Inputs!$C$5),Inputs!$C$37) -> 23.5 | E7: p.p.
A8: Diner | B8: dinergerecht + 2 drankjes | C8: =Inputs!$C$24+2*Inputs!$C$20 -> 26 | D8: =CEILING((C8)*(1+Inputs!$C$5),Inputs!$C$37) -> 31.5 | E8: p.p.
A9: Vergaderzaal/kantoor (10–12 pers.) | B9: dagdeel, max 4 uur | C9: =Inputs!$C$26 -> 225 | D9: =CEILING((C9)*(1+Inputs!$C$5),Inputs!$C$37) -> 270 | E9: per zaal
A10: Vergaderzaal/kantoor (10–12 pers.) | B10: hele dag 08:00–17:00 | C10: =Inputs!$C$27 -> 400 | D10: =CEILING((C10)*(1+Inputs!$C$5),Inputs!$C$37) -> 480 | E10: per zaal
A11: Skybox Londen (6) / Parijs (8) | B11: dagdeel, max 4 uur | C11: =Inputs!$C$28 -> 250 | D11: =CEILING((C11)*(1+Inputs!$C$5),Inputs!$C$37) -> 300 | E11: per skybox
A12: Skybox Londen (6) / Parijs (8) | B12: hele dag 08:00–17:00 | C12: =Inputs!$C$29 -> 500 | D12: =CEILING((C12)*(1+Inputs!$C$5),Inputs!$C$37) -> 600 | E12: per skybox
A13: Congreszaal Amsterdam (max 110) | B13: dagdeel, max 4 uur | C13: =Inputs!$C$30 -> 550 | D13: =CEILING((C13)*(1+Inputs!$C$5),Inputs!$C$37) -> 660 | E13: per zaal
A14: Congreszaal Amsterdam (max 110) | B14: hele dag 08:00–17:00 | C14: =Inputs!$C$31 -> 1000 | D14: =CEILING((C14)*(1+Inputs!$C$5),Inputs!$C$37) -> 1200 | E14: per zaal
A15: Evenementenruimte (20–150) | B15: dagdeel overdag, max 4 uur | C15: =Inputs!$C$32 -> 450 | D15: =CEILING((C15)*(1+Inputs!$C$5),Inputs!$C$37) -> 540 | E15: per zaal
A16: Evenementenruimte (20–150) | B16: avond 18:00–22:00 | C16: =Inputs!$C$33 -> 550 | D16: =CEILING((C16)*(1+Inputs!$C$5),Inputs!$C$37) -> 660 | E16: per zaal
A17: Evenementenruimte (20–150) | B17: hele dag 08:00–17:00 | C17: =Inputs!$C$34 -> 850 | D17: =CEILING((C17)*(1+Inputs!$C$5),Inputs!$C$37) -> 1020 | E17: per zaal
A18: Extra coach-uur (bv. clinic verlengen) | B18: 1 uur coach | C18: =Inputs!$C$13 -> 45 | D18: =CEILING((C18)*(1+Inputs!$C$5),Inputs!$C$37) -> 54 | E18: per uur
A19: Extra baanuur daluren | B19: 1 baan, 1 uur | C19: =Inputs!$C$8 -> 30 | D19: =CEILING((C19)*(1+Inputs!$C$5),Inputs!$C$37) -> 36 | E19: per baan
A20: Extra baanuur piek | B20: 1 baan, 1 uur | C20: =Inputs!$C$9 -> 44 | D20: =CEILING((C20)*(1+Inputs!$C$5),Inputs!$C$37) -> 53 | E20: per baan
A21: Extra baanuur weekend | B21: 1 baan, 1 uur | C21: =Inputs!$C$10 -> 37.5 | D21: =CEILING((C21)*(1+Inputs!$C$5),Inputs!$C$37) -> 45 | E21: per baan
A23: Zaalhuur: inkoopprijzen uit het reserveringssysteem van Poort Padel (AQQO), excl. 21% btw. Een dagdeel is een aaneengesloten blok tot 4 uur.

Sheet Scholen
A1: Schoolarrangementen – daluren ma–vr onder schooltijd (excl. btw)
A2: Kostprijs = banen x uren x daluren + coaches x uren x coachtarief + ballen. Verkoop = kostprijs x (1+marge).
A4: Programma | B4: Leerlingen | C4: Banen | D4: Uren | E4: Coaches | F4: Kostprijs totaal | G4: Kostprijs p.l. | H4: Verkoop p.l. | I4: Verkoop totaal
A5: S1. Gymles op locatie – 1 klas, 60 min | B5: 30 | C5: =CEILING(B5/Inputs!$C$36,1) -> 5 | D5: 1 | E5: 2 | F5: =C5*D5*Inputs!$C$8+E5*D5*Inputs!$C$13+C5*Inputs!$C$16 -> 250 | G5: =F5/B5 -> 8.3333333 | H5: =CEILING((G5)*(1+Inputs!$C$5),Inputs!$C$37) -> 10 | I5: =H5*B5 -> 300
A6: S2. Schoolclinic – 1 klas, 90 min | B6: 30 | C6: =CEILING(B6/Inputs!$C$36,1) -> 5 | D6: 1.5 | E6: 2 | F6: =C6*D6*Inputs!$C$8+E6*D6*Inputs!$C$13+C6*Inputs!$C$16 -> 370 | G6: =F6/B6 -> 12.333333 | H6: =CEILING((G6)*(1+Inputs!$C$5),Inputs!$C$37) -> 15 | I6: =H6*B6 -> 450
A7: S3. Sportdag / sportoriëntatie – 2 klassen, 3 uur roulerend | B7: 60 | C7: =CEILING(B7/2/Inputs!$C$36,1) -> 5 | D7: 3 | E7: 3 | F7: =C7*D7*Inputs!$C$8+E7*D7*Inputs!$C$13+C7*Inputs!$C$16 -> 865 | G7: =F7/B7 -> 14.416667 | H7: =CEILING((G7)*(1+Inputs!$C$5),Inputs!$C$37) -> 17.5 | I7: =H7*B7 -> 1050
A8: S4. Naschools padelprogramma – 4 lessen x 60 min, 8 leerlingen (prijs per les) | B8: 8 | C8: =CEILING(B8/Inputs!$C$36,1) -> 2 | D8: 1 | E8: 1 | F8: =C8*D8*Inputs!$C$8+E8*D8*Inputs!$C$13+C8*Inputs!$C$16 -> 109 | G8: =F8/B8 -> 13.625 | H8: =CEILING((G8)*(1+Inputs!$C$5),Inputs!$C$37) -> 16.5 | I8: =H8*B8 -> 132
A9: S5. Docenten-/teamuitje (zie Arrangementen B, daluren) | B9: 16 | C9: =CEILING(B9/Inputs!$C$11,1) -> 4 | D9: 2 | E9: 2 | F9: =C9*D9*Inputs!$C$8+E9*D9*Inputs!$C$13+C9*Inputs!$C$16 -> 428 | G9: =F9/B9 -> 26.75 | H9: =CEILING((G9)*(1+Inputs!$C$5),Inputs!$C$37) -> 32.5 | I9: =H9*B9 -> 520
A11: S4: prijs per les per leerling; een reeks van 4 lessen = 4x. Vervoer naar Poort Padel is voor de school (bushalte op 100 m).

Sheet Offerte
A1: Snelle offerte – vul de blauwe cellen in
A3: Aantal deelnemers | B3: 24 | C3: pers.
A4: Pakket (1–5: A, B, C, D, E) | B4: 2 | C4: nr
A5: Tijdvak (1 = daluren, 2 = piek, 3 = weekend) | B5: 2 | C5: nr
A6: Borrelarrangement erbij? (1 = ja) | B6: 1 | C6: ja/nee
A7: Lunch erbij? (1 = ja) | B7: 0 | C7: ja/nee
A8: Diner erbij? (1 = ja) | B8: 0 | C8: ja/nee
A9: Aantal vergaderzalen (dagdeel) | B9: 0 | C9: zalen
A11: Berekening
A12: Gekozen pakket | B12: =INDEX(Arrangementen!$A$5:$A$9,B4) -> B. Clinic + vrij spel (2 uur)
A13: Verkoopprijs pakket p.p. | B13: =INDEX(Arrangementen!$I$5:$K$9,B4,B5) -> 34
A14: Pakket totaal | B14: =B13*B3 -> 816
A15: Borrel p.p. | B15: =B6*'Add-ons'!$D$5 -> 14
A16: Lunch p.p. | B16: =B7*'Add-ons'!$D$7 -> 0
A17: Diner p.p. | B17: =B8*'Add-ons'!$D$8 -> 0
A18: Horeca totaal | B18: =(B15+B16+B17)*B3 -> 336
A19: Zaalhuur totaal (vergaderzalen, dagdeel) | B19: =B9*'Add-ons'!$D$9 -> 0
A20: TOTAAL excl. btw | B20: =B14+B18+B19 -> 1152
A21: Prijs per persoon excl. btw | B21: =IF(B3>0,B20/B3,0) -> 48
A22: Waarvan marge All Court Academy (indicatie) | B22: =B20-B20/(1+Inputs!$C$5) -> 192
A23: Check: minimum 16 personen? | B23: =IF(B3>=16,"OK","LET OP: Poort Padel vraagt minimaal 16 personen") -> OK

Sheet Padel Dating
A1: Padel Dating – kostenplaatje en marge (zaterdag 7 november 2026, 19:00–22:00)
A2: Blauw = invoer. Geel = nog te onderhandelen of te bevestigen. Marge = winst als % van de omzet excl. btw (doel 30%).
A4: Deelnemers (12 dames + 12 heren) | B4: 24 | C4: pers. | D4: Max 24, min 12
A5: Verkoopprijs p.p. incl. btw | B5: 49.5 | C5: € | D5: Poster: €49,50
A6: Btw | B6: =Inputs!$C$6 -> 0.21 | C6: % | D6: Inputs
A7: Banen (4 spelers per baan, iedereen tegelijk) | B7: 6 | C7: banen | D7: 24 deelnemers = 6 banen; 16 = 4; 12 = 3
A8: Uren per baan | B8: 2 | C8: uur | D8: Besluit Lars 20 september 2026: 2 uur banen, 19:00 tot 21:00
A9: Baantarief per uur (afspraak Poort Padel) | B9: 22.5 | C9: €/uur | D9: Weekend €37,50 op Playtomic; voorstel Lars €22,50
A10: Betaalde hosts (Lars zelf niet meegerekend) | B10: 1 | C10: pers. | D10: Lars host zelf plus 1 betaalde host
A11: Uren per host | B11: 3.5 | C11: uur | D11: Opbouw 17:45 tot einde 22:00 (incl. opruimen)
A12: Hosttarief per uur | B12: =Inputs!$C$13 -> 45 | C12: €/uur | D12: Inputs (aanname coachtarief)
A13: Drankjes p.p. (alleen welkomstdrankje) | B13: 1 | C13: stuks | D13: Besluit Lars: welkomstdrankje + hapjes inbegrepen, rest eigen rekening
A14: Inkoopprijs per drankje (afspraak Poort Padel) | B14: 4.08 | C14: € | D14: Afspraak: welkomstdrankje + 4 hapjes samen €8,00 p.p.
A15: Hapjes p.p. (aantal) | B15: 4 | C15: stuks
A16: Prijs per hapje | B16: =Inputs!$C$21 -> 0.98 | C16: € | D16: Inputs, teamschotel
A17: Materialen (ballen, stickers, matchkaartjes, prints) | B17: 31 | C17: €
A18: Aantal winnaars (1 dame + 1 heer) | B18: 2 | C18: pers. | D18: Elke winnaar wint een date voor 2
A19: Waarde datevoucher BoutiQ per winnaar | B19: 50 | C19: € | D19: Keuze Lars: €50
A20: BoutiQ sponsort de vouchers? (1 = ja, 0 = ACA betaalt) | B20: 1 | C20: ja/nee | D20: Lars vraagt het na bij BoutiQ, Grote Markt 3
A21: Gratis baanuren voor matches (0 = geen, besluit Lars) | B21: 0 | C21: matches | D21: Vervallen op 20 september 2026
A22: Poort Padel geeft de match-baanuren gratis? (1 = ja) | B22: 1 | C22: ja/nee | D22: Onderhandelen: matches komen terug als nieuwe boekingen
A23: Doelmarge (% van omzet excl. btw) | B23: 0.3 | C23: % | D23: Keuze Lars: 30%
A25: Berekening bij de invoer hierboven
A26: Omzet incl. btw | B26: =$B$4*$B$5 -> 1188
A27: Omzet excl. btw | B27: =$B$4*$B$5/(1+$B$6) -> 981.81818
A28: Baanhuur | B28: =$B$7*$B$8*$B$9 -> 270
A29: Hosts | B29: =$B$10*$B$11*$B$12 -> 157.5
A30: Welkomstdrankje | B30: =$B$4*$B$13*$B$14 -> 97.92
A31: Hapjes | B31: =$B$4*$B$15*$B$16 -> 94.08
A32: Materialen | B32: =$B$17 -> 31
A33: Datevouchers BoutiQ (0 als BoutiQ sponsort) | B33: =IF($B$20=1,0,$B$18*$B$19) -> 0
A34: Gratis baanuren voor matches (0 als Poort Padel ze geeft) | B34: =IF($B$22=1,0,$B$21*$B$9) -> 0
A35: Totale kosten | B35: =SUM(B28:B34) -> 650.5
A36: Kostprijs per persoon | B36: =$B$35/$B$4 -> 27.104167
A37: Winst excl. btw | B37: =$B$27-$B$35 -> 331.31818
A38: Marge (% van omzet excl. btw) | B38: =$B$37/$B$27 -> 0.3374537
A39: Naar Poort Padel (banen + drankjes + hapjes + match-uren) | B39: =$B$28+$B$30+$B$31+$B$34 -> 462
A40: Naar Poort Padel per persoon | B40: =$B$39/$B$4 -> 19.25
A41: Break-even aantal deelnemers | B41: =CEILING(($B$28+$B$29+$B$32+$B$33+$B$34)/($B$5/(1+$B$6)-$B$13*$B$14-$B$15*$B$16),1) -> 14
A42: Benodigde prijs incl. btw voor de doelmarge | B42: =$B$35/(1-$B$23)/$B$4*(1+$B$6) -> 46.851488
...

Sheet Padel & Quiz
A1: Padel & Quiz – kostenplaatje en marge (zaterdagavond, teams van 4)
A2: Blauw = invoer. Geel = te bevestigen bij Poort Padel. Marge = winst als % van de omzet excl. btw (doel 30%). Prijzen worden door Poort Padel gegeven (kosten €0).
A4: Deelnemers (quizteams van 4) | B4: 32 | C4: pers. | D4: Min 24, doel 32, max 40; alleen, met 2 of met 4 inschrijven
A5: Verkoopprijs p.p. incl. btw | B5: 39.5 | C5: € | D5: Advies €39,50 (Houten €27,50 zonder host en hapjes; Padel Dating €49,50)
A6: Btw | B6: =Inputs!$C$6 -> 0.21 | C6: % | D6: Inputs
A7: Uren per baan | B7: 1.5 | C7: uur | D7: Besluit Lars: 1,5 uur Mexicano, 18:00 tot 19:30
A8: Baantarief per uur (afspraak Poort Padel) | B8: 22.5 | C8: €/uur | D8: Besluit Lars: banen worden gehuurd, €22,50 of lager; niet gratis
A9: Hosturen Lars (host + quizmaster) | B9: 5 | C9: uur | D9: 17:00 opbouw tot 22:00
A10: Hosttarief per uur | B10: =Inputs!$C$13 -> 45 | C10: €/uur | D10: Inputs (€45 excl. btw)
A11: Welkomstdrankje + hapjes p.p. (afspraak Poort Padel) | B11: 8 | C11: € | D11: Zelfde arrangement als Padel Dating
A12: Materialen | B12: 0 | C12: € | D12: Besluit Lars: geen materiaalkosten; printen en ballen uit eigen voorraad, scherm en geluid van Poort Padel
A13: Poort Padel geeft de prijzen? (1 = ja, 0 = ACA betaalt) | B13: 1 | C13: ja/nee | D13: Afspraak Lars: Poort Padel geeft de prijzen
A14: Waarde prijzenpakket als ACA het zelf betaalt | B14: 420 | C14: € | D14: 9 baanuren tegen lijstprijs + drankjes, hapjes, ballen en grips; winkelwaarde ± €500 (events/padel-quiz.md par. 5)
A15: Doelmarge (% van omzet excl. btw) | B15: 0.3 | C15: % | D15: Keuze Lars: 30%
A16: Weekendtarief lijstprijs per baanuur | B16: 37.5 | C16: €/uur | D16: Playtomic za/zo, geverifieerd
A17: Baromzet p.p. tijdens quiz en nazit (schatting) | B17: 15 | C17: € | D17: 3 drankjes à €4 + hapje; Engelse benchmark £12 p.p. in 2,5 uur
A18: Inkoop prijzenpakket voor Poort Padel | B18: 85 | C18: € | D18: Drankjes, hapjes, ballen, grips; baanuren kosten geen cash
A20: Berekening bij de invoer hierboven
A21: Banen (4 spelers per baan) | B21: =CEILING($B$4/4,1) -> 8
A22: Omzet incl. btw | B22: =$B$4*$B$5 -> 1264
A23: Omzet excl. btw | B23: =$B$4*$B$5/(1+$B$6) -> 1044.6281
A24: Baanhuur | B24: =CEILING($B$4/4,1)*$B$7*$B$8 -> 270
A25: Welkomstdrankje + hapjes | B25: =$B$4*$B$11 -> 256
A26: Host / quizmaster (Lars) | B26: =$B$9*$B$10 -> 225
A27: Materialen | B27: =$B$12 -> 0
A28: Prijzen (0 als Poort Padel ze geeft) | B28: =IF($B$13=1,0,$B$14) -> 0
A29: Totale kosten | B29: =SUM(B24:B28) -> 751
A30: Kostprijs per persoon | B30: =$B$29/$B$4 -> 23.46875
A31: Winst excl. btw | B31: =$B$23-$B$29 -> 293.6281
A32: Marge (% van omzet excl. btw) | B32: =$B$31/$B$23 -> 0.28108386
A33: Naar Poort Padel (banen + drankje + hapjes) | B33: =$B$24+$B$25 -> 526
A34: Benodigde prijs incl. btw voor de doelmarge | B34: =$B$29/(1-$B$15)/$B$4*(1+$B$6) -> 40.567411
A35: Maximaal baantarief per uur bij deze prijs en doelmarge | B35: =($B$23*(1-$B$15)-$B$25-$B$26-$B$27-$B$28)/(CEILING($B$4/4,1)*$B$7) -> 20.853306
A36: Break-even aantal deelnemers (banen schalen mee) | B36: =CEILING(($B$26+$B$27+$B$28)/($B$5/(1+$B$6)-$B$11-$B$7*$B$8/4),1) -> 14
A37: Lars totaal (winst + hostloon) | B37: =$B$31+$B$26 -> 518.6281
A38: Poort Padel: baromzet tijdens quiz en nazit (schatting) | B38: =$B$4*$B$17 -> 480
A39: Poort Padel: totaal (baanhuur + arrangement + bar) | B39: =$B$33+$B$4*$B$17 -> 1006
A40: Poort Padel: totaal na inkoop prijzen | B40: =$B$33+$B$4*$B$17-IF($B$13=1,$B$18,0) -> 921
A41: Wat de korting Poort Padel kost t.o.v. het weekendtarief | B41: =CEILING($B$4/4,1)*$B$7*($B$16-$B$8) -> 180
A43: Per deelnemersaantal (prijs, tarief en arrangement volgen de invoer hierboven)
...

Sheet Legenda
A1: Doel | B1: Prijslijst voor All Court Academy op basis van inkoop bij Poort Padel plus een winstmarge (standaard 20%).
A2: Blauw | B2: Invoercellen. Aanpassen mag.
A3: Geel | B3: Aanname die nog geverifieerd moet worden bij Poort Padel (horeca-arrangementen, rackethuur) of intern (coachtarief).
A4: Zwart | B4: Formules. Niet overschrijven.
A5: Groen | B5: Verwijzing naar een ander tabblad.
A6: Bron baanhuur | B6: Playtomic, club Poort Padel, tarieven bekeken op 6 en 9 september 2026.
A7: Bron horeca | B7: Menukaart Poort Padel (PDF, juni 2026).
A8: Bron zalen | B8: reserveren.poortpadel.nl (AQQO) – capaciteiten en prijzen uit stap 2 van de reserveringswizard, 6 sep 2026.
A9: Btw | B9: Alle bedragen excl. btw. Sportbeoefening/clinics vallen doorgaans onder 9%, zaalhuur onder 21%. Check met boekhouder.
